<?xml version="1.0" ?>
<!-- =================================================================================== -->
<!-- |    This document was autogenerated by xacro from nova_carter.urdf.xacro         | -->
<!-- |    EDITING THIS FILE BY HAND IS NOT RECOMMENDED                                 | -->
<!-- =================================================================================== -->
<!--
Copyright (c) 2024, NVIDIA CORPORATION. All rights reserved.

NVIDIA CORPORATION and its licensors retain all intellectual property
and proprietary rights in and to this software, related documentation
and any modifications thereto. Any use, reproduction, disclosure or
distribution of this software and related documentation without an express
license agreement from NVIDIA CORPORATION is strictly prohibited.
-->
<robot name="please_specify_carter_id_name">
  <!-- Platform Structure -->
  <!-- Main link of Nova Carter: Origin is at center of rotation on the ground (centered between
  two large wheels) -->
  <link name="base_link"/>
  <!-- Joints defining the platform structure -->
  <joint name="joint_swing_left" type="continuous">
    <origin rpy="0.0 0.0 -1.5707963267948966" xyz="0.132296 0.031188 0.000002"/>
    <parent link="nova_carter_caster_frame_base"/>
    <child link="caster_swivel_left"/>
    <axis xyz="1.0 0.0 0.0"/>
    <dynamics damping="0.01" friction="0.1"/>
  </joint>
  <joint name="joint_swing_right" type="continuous">
    <origin rpy="0.0 0.0 -1.5707963267948966" xyz="-0.1322037 0.0311879 0.0000001"/>
    <parent link="nova_carter_caster_frame_base"/>
    <child link="caster_swivel_right"/>
    <axis xyz="1.0 0.0 0.0"/>
    <dynamics damping="0.01" friction="0.1"/>
  </joint>
  <joint name="joint_wheel_left" type="continuous">
    <origin rpy="-1.5707963267948966 0.0 0.0" xyz="0.0 0.1726 0.14"/>
    <parent link="nova_carter"/>
    <child link="wheel_left"/>
    <axis xyz="0.0 0.0 1.0"/>
    <dynamics damping="0.01" friction="0.1"/>
  </joint>
  <joint name="joint_wheel_right" type="continuous">
    <origin rpy="-1.5707963267948966 0.0 0.0" xyz="0.0 -0.1726 0.14"/>
    <parent link="nova_carter"/>
    <child link="wheel_right"/>
    <axis xyz="0.0 0.0 1.0"/>
    <dynamics damping="0.01" friction="0.1"/>
  </joint>
  <joint name="joint_caster_base" type="revolute">
    <origin rpy="-1.5707963267948966 0.0 1.5707963267948966" xyz="-0.47195 0.0 0.22289"/>
    <parent link="nova_carter"/>
    <child link="nova_carter_caster_frame_base"/>
    <axis xyz="0.0 0.0 1.0"/>
    <limit effort="100000000.0" lower="-0.0349066" upper="0.0349066" velocity="0.0"/>
    <dynamics damping="10.0" friction="10.0"/>
  </joint>
  <joint name="joint_caster_left" type="continuous">
    <origin rpy="1.5707963267948966 -1.5707963267948966 0.0" xyz="-0.1153999 -0.0230851 0.0399971"/>
    <parent link="caster_swivel_left"/>
    <child link="caster_wheel_left"/>
    <axis xyz="0.0 0.0 1.0"/>
    <dynamics damping="0.1" friction="0.1"/>
  </joint>
  <joint name="joint_caster_right" type="continuous">
    <origin rpy="1.5707963267948966 -1.5707963267948966 0.0" xyz="-0.1154 -0.022989 0.039999"/>
    <parent link="caster_swivel_right"/>
    <child link="caster_wheel_right"/>
    <axis xyz="0.0 0.0 1.0"/>
    <dynamics damping="0.1" friction="0.1"/>
  </joint>
  <joint name="nova_carter_joint" type="fixed">
    <origin rpy="0.0 0.0 0.0" xyz="0.0 0.0 0.0"/>
    <parent link="base_link"/>
    <child link="nova_carter"/>
  </joint>
  <!-- Links and Meshes -->
  <link name="caster_swivel_left">
    <inertial>
      <origin rpy="0.0 0.0 0.0" xyz="0.0 0.0 0.0"/>
      <mass value="0.34581223130226135"/>
      <inertia ixx="0.000165319" ixy="0.0" ixz="0.0" iyy="0.000474739" iyz="0.0" izz="0.000460723"/>
    </inertial>
    <visual>
      <origin rpy="0.0 0.0 0.0" xyz="-0.000002 0.000004 -0.000002"/>
      <geometry>
        <mesh filename="package://nova_carter_description/meshes/caster_swivel.obj"/>
      </geometry>
    </visual>
  </link>
  <link name="caster_swivel_right">
    <inertial>
      <origin rpy="0.0 0.0 0.0" xyz="0.0 0.0 0.0"/>
      <mass value="0.34581223130226135"/>
      <inertia ixx="0.000165319" ixy="0.0" ixz="0.0" iyy="0.000474739" iyz="0.0" izz="0.000460723"/>
    </inertial>
    <visual>
      <origin rpy="0.0 0.0 0.0" xyz="-0.0000021 0.0 -0.0000001"/>
      <geometry>
        <mesh filename="package://nova_carter_description/meshes/caster_swivel.obj"/>
      </geometry>
    </visual>
  </link>
  <link name="caster_wheel_left">
    <inertial>
      <origin rpy="0.0 0.0 0.0" xyz="0.0 0.0 0.0"/>
      <mass value="0.1"/>
      <inertia ixx="0.000147704" ixy="0.0" ixz="0.0" iyy="0.000147704" iyz="0.0" izz="0.000285012"/>
    </inertial>
    <visual>
      <origin rpy="3.141592653589793 0.0 0.0" xyz="0.0 -0.000005 -0.023039"/>
      <geometry>
        <mesh filename="package://nova_carter_description/meshes/caster_wheel.obj"/>
      </geometry>
    </visual>
    <collision>
      <origin rpy="3.141592653589793 0.0 0.0" xyz="0.0000001 -0.0000045 -0.0230392"/>
      <geometry>
        <cylinder length="0.025" radius="0.0755"/>
      </geometry>
      <surface>
        <friction>
          <ode>
            <mu>1.0</mu>
            <mu2>1.0</mu2>
          </ode>
        </friction>
      </surface>
    </collision>
  </link>
  <link name="caster_wheel_right">
    <inertial>
      <origin rpy="0.0 0.0 0.0" xyz="0.0 0.0 0.0"/>
      <mass value="0.1"/>
      <inertia ixx="0.000147704" ixy="0.0" ixz="0.0" iyy="0.000147704" iyz="0.0" izz="0.000285012"/>
    </inertial>
    <visual>
      <origin rpy="3.141592653589793 0.0 0.0" xyz="0.0 -0.000005 -0.0230391"/>
      <geometry>
        <mesh filename="package://nova_carter_description/meshes/caster_wheel.obj"/>
      </geometry>
    </visual>
    <collision>
      <origin rpy="3.141592653589793 0.0 0.0" xyz="0.0 -0.0000046 -0.0230391"/>
      <geometry>
        <cylinder length="0.025" radius="0.0755"/>
      </geometry>
      <surface>
        <friction>
          <ode>
            <mu>1.0</mu>
            <mu2>1.0</mu2>
          </ode>
        </friction>
      </surface>
    </collision>
  </link>
  <link name="nova_carter">
    <inertial>
      <origin rpy="0.0 0.0 0.0" xyz="-0.209765 0.0 0.282844"/>
      <mass value="52.90850067138672"/>
      <inertia ixx="0.969161" ixy="0.0" ixz="0.0" iyy="2.39801" iyz="0.0" izz="2.5126"/>
    </inertial>
    <visual>
      <origin rpy="0.0 0.0 0.0" xyz="0.0 0.0 0.0"/>
      <geometry>
        <mesh filename="package://nova_carter_description/meshes/chassis_link.obj"/>
      </geometry>
    </visual>
    <collision>
      <origin rpy="0.0 0.0 0.0" xyz="0.0 0.0 0.0"/>
      <geometry>
        <mesh filename="package://nova_carter_description/meshes/chassis_link.obj"/>
      </geometry>
    </collision>
  </link>
  <link name="nova_carter_caster_frame_base">
    <inertial>
      <origin rpy="0.0 0.0 0.0" xyz="0.0 0.0 0.0"/>
      <mass value="1.687524437904358"/>
      <inertia ixx="0.00163336" ixy="0.0" ixz="0.0" iyy="0.0136019" iyz="0.0" izz="0.01298"/>
    </inertial>
    <visual>
      <origin rpy="0.0 0.0 0.0" xyz="0.0 0.0 0.0"/>
      <geometry>
        <mesh filename="package://nova_carter_description/meshes/caster_frame_base.obj"/>
      </geometry>
    </visual>
  </link>
  <link name="wheel_left">
    <inertial>
      <origin rpy="0.0 0.0 0.0" xyz="0.0 0.0 0.0"/>
      <mass value="1.0"/>
      <inertia ixx="0.00389878" ixy="0.0" ixz="0.0" iyy="0.00389878" iyz="0.0" izz="0.00712177"/>
    </inertial>
    <visual>
      <origin rpy="0.0 0.0 0.0" xyz="-0.0 0.0 0.034"/>
      <geometry>
        <mesh filename="package://nova_carter_description/meshes/nova_carter_wheel_left.obj"/>
      </geometry>
    </visual>
    <collision>
      <origin rpy="3.141592653589793 0.0 -0.5235988" xyz="-0.0 0.0 0.034"/>
      <geometry>
        <cylinder length="0.02" radius="0.14"/>
      </geometry>
      <surface>
        <friction>
          <ode>
            <mu>1.0</mu>
            <mu2>1.0</mu2>
          </ode>
        </friction>
      </surface>
    </collision>
    <collision>
      <origin rpy="3.141592653589793 0.0 -0.5235988" xyz="-0.0 0.0 0.034"/>
      <geometry>
        <cylinder length="0.06" radius="0.125"/>
      </geometry>
      <surface>
        <friction>
          <ode>
            <mu>1.0</mu>
            <mu2>1.0</mu2>
          </ode>
        </friction>
      </surface>
    </collision>
    <collision>
      <origin rpy="3.141592653589793 0.0 -0.5235988" xyz="-0.0 0.0 0.034"/>
      <geometry>
        <cylinder length="0.08" radius="0.1"/>
      </geometry>
      <surface>
        <friction>
          <ode>
            <mu>1.0</mu>
            <mu2>1.0</mu2>
          </ode>
        </friction>
      </surface>
    </collision>
  </link>
  <link name="wheel_right">
    <inertial>
      <origin rpy="0.0 0.0 0.0" xyz="0.0 0.0 0.0"/>
      <mass value="1.0"/>
      <inertia ixx="0.00389878" ixy="0.0" ixz="0.0" iyy="0.00389878" iyz="0.0" izz="0.00712177"/>
    </inertial>
    <visual>
      <origin rpy="0.0 0.0 0.0" xyz="-0.0 0.0 -0.034"/>
      <geometry>
        <mesh filename="package://nova_carter_description/meshes/nova_carter_wheel_left.obj"/>
      </geometry>
    </visual>
    <collision>
      <origin rpy="0.0 0.0 -2.6179938" xyz="-0.0 0.0 -0.034"/>
      <geometry>
        <cylinder length="0.02" radius="0.14"/>
      </geometry>
      <surface>
        <friction>
          <ode>
            <mu>1.0</mu>
            <mu2>1.0</mu2>
          </ode>
        </friction>
      </surface>
    </collision>
    <collision>
      <origin rpy="0.0 0.0 -2.6179938" xyz="-0.0 0.0 -0.034"/>
      <geometry>
        <cylinder length="0.06" radius="0.125"/>
      </geometry>
      <surface>
        <friction>
          <ode>
            <mu>1.0</mu>
            <mu2>1.0</mu2>
          </ode>
        </friction>
      </surface>
    </collision>
    <collision>
      <origin rpy="0.0 0.0 -2.6179938" xyz="-0.0 0.0 -0.034"/>
      <geometry>
        <cylinder length="0.08" radius="0.1"/>
      </geometry>
      <surface>
        <friction>
          <ode>
            <mu>1.0</mu>
            <mu2>1.0</mu2>
          </ode>
        </friction>
      </surface>
    </collision>
  </link>
  <!-- Stereo cameras  -->
  <!-- <xacro:hawk_camera name="front_stereo" parent="base_link">
    <origin xyz="0.100300 0.075000 0.344400" rpy="0.0 0.0 0.0"/>
  </xacro:hawk_camera> -->
  <!-- <xacro:hawk_camera name="left_stereo" parent="base_link">
    <origin xyz="-0.430400 0.150000 0.344400" rpy="0.0 0.0 ${M_PI/2}"/>
  </xacro:hawk_camera>

  <xacro:hawk_camera name="right_stereo" parent="base_link">
    <origin xyz="-0.280400 -0.150000 0.344400" rpy="0.0 0.0 ${-M_PI/2}"/>
  </xacro:hawk_camera>

  <xacro:hawk_camera name="back_stereo" parent="base_link">
    <origin xyz="-0.563700 -0.075000 0.344400" rpy="0.0 0.0 ${M_PI}"/>
  </xacro:hawk_camera> -->
  <!-- Fisheye cameras  -->
  <!-- <xacro:owl_camera name="front_fisheye" parent="base_link">
    <origin xyz="0.107300 0.0 0.374400" rpy="0.0 0.0 0.0"/>
  </xacro:owl_camera>

  <xacro:owl_camera name="left_fisheye" parent="base_link">
    <origin xyz="-0.231700 0.157100 0.344400" rpy="0.0 0.0 ${M_PI/2}"/>
  </xacro:owl_camera>

  <xacro:owl_camera name="right_fisheye" parent="base_link">
    <origin xyz="-0.231700 -0.157100 0.344400" rpy="0.0 0.0 ${-M_PI/2}"/>
  </xacro:owl_camera>

  <xacro:owl_camera name="back_fisheye" parent="base_link">
    <origin xyz="-0.570700 0.0 0.374400" rpy="0.0 0.0 ${M_PI}"/>
  </xacro:owl_camera> -->
  <!-- 3D LIDAR -->
  <!-- <xacro:pandar_xt32_lidar name="front" parent="base_link">
    <origin xyz="-0.231700 0.0 0.526300" rpy="0.0 0.0 0.0"/>
  </xacro:pandar_xt32_lidar> -->
  <!-- 2D LIDARs -->
  <!-- <xacro:rplidar_s2e_lidar name="front" parent="base_link">
    <origin xyz="0.026000 0.0 0.418000" rpy="0.0 0.0 ${M_PI}"/>
  </xacro:rplidar_s2e_lidar> -->
  <!-- 
  <xacro:rplidar_s2e_lidar name="back" parent="base_link">
    <origin xyz="-0.489400 0.0 0.418000" rpy="0.0 0.0 0.0"/>
  </xacro:rplidar_s2e_lidar> -->
  <!-- Chassis IMU -->
  <!-- <link name="chassis_imu"/>
  <joint name="chassis_imu_joint" type="fixed">
      <origin xyz="-0.218480 0.024460 0.156430" rpy="0.0 0.0 0.0"/>
      <parent link="base_link"/>
      <child link="chassis_imu"/>
  </joint> -->
</robot>
