<?xml version="1.0" ?>
<!-- =================================================================================== -->
<!-- |    This document was autogenerated by xacro from ur_nova.urdf.xacro             | -->
<!-- |    EDITING THIS FILE BY HAND IS NOT RECOMMENDED                                 | -->
<!-- =================================================================================== -->
<robot name="ur_nova">
  <link name="base_footprint"/>
  <!-- Joints defining the platform structure -->
  <joint name="joint_swing_left" type="continuous">
    <origin rpy="0.0 0.0 -1.5707963267948966" xyz="0.132296 0.031188 0.000002"/>
    <parent link="nova_carter_caster_frame_base"/>
    <child link="caster_swivel_left"/>
    <axis xyz="1.0 0.0 0.0"/>
    <dynamics damping="0.01" friction="0.1"/>
  </joint>
  <joint name="joint_swing_right" type="continuous">
    <origin rpy="0.0 0.0 -1.5707963267948966" xyz="-0.1322037 0.0311879 0.0000001"/>
    <parent link="nova_carter_caster_frame_base"/>
    <child link="caster_swivel_right"/>
    <axis xyz="1.0 0.0 0.0"/>
    <dynamics damping="0.01" friction="0.1"/>
  </joint>
  <joint name="joint_wheel_left" type="continuous">
    <origin rpy="-1.5707963267948966 0.0 0.0" xyz="0.0 0.1726 0.14"/>
    <parent link="nova_carter"/>
    <child link="wheel_left"/>
    <axis xyz="0.0 0.0 1.0"/>
    <dynamics damping="0.01" friction="0.1"/>
  </joint>
  <joint name="joint_wheel_right" type="continuous">
    <origin rpy="-1.5707963267948966 0.0 0.0" xyz="0.0 -0.1726 0.14"/>
    <parent link="nova_carter"/>
    <child link="wheel_right"/>
    <axis xyz="0.0 0.0 1.0"/>
    <dynamics damping="0.01" friction="0.1"/>
  </joint>
  <joint name="joint_caster_base" type="revolute">
    <origin rpy="-1.5707963267948966 0.0 1.5707963267948966" xyz="-0.47195 0.0 0.22289"/>
    <parent link="nova_carter"/>
    <child link="nova_carter_caster_frame_base"/>
    <axis xyz="0.0 0.0 1.0"/>
    <limit effort="100000000.0" lower="-0.0349066" upper="0.0349066" velocity="0.0"/>
    <dynamics damping="10.0" friction="10.0"/>
  </joint>
  <joint name="joint_caster_left" type="continuous">
    <origin rpy="1.5707963267948966 -1.5707963267948966 0.0" xyz="-0.1153999 -0.0230851 0.0399971"/>
    <parent link="caster_swivel_left"/>
    <child link="caster_wheel_left"/>
    <axis xyz="0.0 0.0 1.0"/>
    <dynamics damping="0.1" friction="0.1"/>
  </joint>
  <joint name="joint_caster_right" type="continuous">
    <origin rpy="1.5707963267948966 -1.5707963267948966 0.0" xyz="-0.1154 -0.022989 0.039999"/>
    <parent link="caster_swivel_right"/>
    <child link="caster_wheel_right"/>
    <axis xyz="0.0 0.0 1.0"/>
    <dynamics damping="0.1" friction="0.1"/>
  </joint>
  <joint name="nova_carter_joint" type="fixed">
    <origin rpy="0.0 0.0 0.0" xyz="0.0 0.0 0.0"/>
    <parent link="base_footprint"/>
    <child link="nova_carter"/>
  </joint>
  <!-- Links and Meshes -->
  <link name="caster_swivel_left">
    <inertial>
      <origin rpy="0.0 0.0 0.0" xyz="0.0 0.0 0.0"/>
      <mass value="0.34581223130226135"/>
      <inertia ixx="0.000165319" ixy="0.0" ixz="0.0" iyy="0.000474739" iyz="0.0" izz="0.000460723"/>
    </inertial>
    <visual>
      <origin rpy="0.0 0.0 0.0" xyz="-0.000002 0.000004 -0.000002"/>
      <geometry>
        <mesh filename="package://nova_carter_description/meshes/caster_swivel.obj"/>
      </geometry>
    </visual>
  </link>
  <link name="caster_swivel_right">
    <inertial>
      <origin rpy="0.0 0.0 0.0" xyz="0.0 0.0 0.0"/>
      <mass value="0.34581223130226135"/>
      <inertia ixx="0.000165319" ixy="0.0" ixz="0.0" iyy="0.000474739" iyz="0.0" izz="0.000460723"/>
    </inertial>
    <visual>
      <origin rpy="0.0 0.0 0.0" xyz="-0.0000021 0.0 -0.0000001"/>
      <geometry>
        <mesh filename="package://nova_carter_description/meshes/caster_swivel.obj"/>
      </geometry>
    </visual>
  </link>
  <link name="caster_wheel_left">
    <inertial>
      <origin rpy="0.0 0.0 0.0" xyz="0.0 0.0 0.0"/>
      <mass value="0.1"/>
      <inertia ixx="0.000147704" ixy="0.0" ixz="0.0" iyy="0.000147704" iyz="0.0" izz="0.000285012"/>
    </inertial>
    <visual>
      <origin rpy="3.141592653589793 0.0 0.0" xyz="0.0 -0.000005 -0.023039"/>
      <geometry>
        <mesh filename="package://nova_carter_description/meshes/caster_wheel.obj"/>
      </geometry>
    </visual>
    <collision>
      <origin rpy="3.141592653589793 0.0 0.0" xyz="0.0000001 -0.0000045 -0.0230392"/>
      <geometry>
        <cylinder length="0.025" radius="0.0755"/>
      </geometry>
      <surface>
        <friction>
          <ode>
            <mu>1.0</mu>
            <mu2>1.0</mu2>
          </ode>
        </friction>
      </surface>
    </collision>
  </link>
  <link name="caster_wheel_right">
    <inertial>
      <origin rpy="0.0 0.0 0.0" xyz="0.0 0.0 0.0"/>
      <mass value="0.1"/>
      <inertia ixx="0.000147704" ixy="0.0" ixz="0.0" iyy="0.000147704" iyz="0.0" izz="0.000285012"/>
    </inertial>
    <visual>
      <origin rpy="3.141592653589793 0.0 0.0" xyz="0.0 -0.000005 -0.0230391"/>
      <geometry>
        <mesh filename="package://nova_carter_description/meshes/caster_wheel.obj"/>
      </geometry>
    </visual>
    <collision>
      <origin rpy="3.141592653589793 0.0 0.0" xyz="0.0 -0.0000046 -0.0230391"/>
      <geometry>
        <cylinder length="0.025" radius="0.0755"/>
      </geometry>
      <surface>
        <friction>
          <ode>
            <mu>1.0</mu>
            <mu2>1.0</mu2>
          </ode>
        </friction>
      </surface>
    </collision>
  </link>
  <link name="nova_carter">
    <inertial>
      <origin rpy="0.0 0.0 0.0" xyz="-0.209765 0.0 0.282844"/>
      <mass value="52.90850067138672"/>
      <inertia ixx="0.969161" ixy="0.0" ixz="0.0" iyy="2.39801" iyz="0.0" izz="2.5126"/>
    </inertial>
    <visual>
      <origin rpy="0.0 0.0 0.0" xyz="0.0 0.0 0.0"/>
      <geometry>
        <mesh filename="package://nova_carter_description/meshes/chassis_link.obj"/>
      </geometry>
    </visual>
    <collision>
      <origin rpy="0.0 0.0 0.0" xyz="0.0 0.0 0.0"/>
      <geometry>
        <mesh filename="package://nova_carter_description/meshes/chassis_link.obj"/>
      </geometry>
    </collision>
  </link>
  <link name="nova_carter_caster_frame_base">
    <inertial>
      <origin rpy="0.0 0.0 0.0" xyz="0.0 0.0 0.0"/>
      <mass value="1.687524437904358"/>
      <inertia ixx="0.00163336" ixy="0.0" ixz="0.0" iyy="0.0136019" iyz="0.0" izz="0.01298"/>
    </inertial>
    <visual>
      <origin rpy="0.0 0.0 0.0" xyz="0.0 0.0 0.0"/>
      <geometry>
        <mesh filename="package://nova_carter_description/meshes/caster_frame_base.obj"/>
      </geometry>
    </visual>
  </link>
  <link name="wheel_left">
    <inertial>
      <origin rpy="0.0 0.0 0.0" xyz="0.0 0.0 0.0"/>
      <mass value="1.0"/>
      <inertia ixx="0.00389878" ixy="0.0" ixz="0.0" iyy="0.00389878" iyz="0.0" izz="0.00712177"/>
    </inertial>
    <visual>
      <origin rpy="0.0 0.0 0.0" xyz="-0.0 0.0 0.034"/>
      <geometry>
        <mesh filename="package://nova_carter_description/meshes/nova_carter_wheel_left.obj"/>
      </geometry>
    </visual>
    <collision>
      <origin rpy="3.141592653589793 0.0 -0.5235988" xyz="-0.0 0.0 0.034"/>
      <geometry>
        <cylinder length="0.02" radius="0.14"/>
      </geometry>
      <surface>
        <friction>
          <ode>
            <mu>1.0</mu>
            <mu2>1.0</mu2>
          </ode>
        </friction>
      </surface>
    </collision>
    <collision>
      <origin rpy="3.141592653589793 0.0 -0.5235988" xyz="-0.0 0.0 0.034"/>
      <geometry>
        <cylinder length="0.06" radius="0.125"/>
      </geometry>
      <surface>
        <friction>
          <ode>
            <mu>1.0</mu>
            <mu2>1.0</mu2>
          </ode>
        </friction>
      </surface>
    </collision>
    <collision>
      <origin rpy="3.141592653589793 0.0 -0.5235988" xyz="-0.0 0.0 0.034"/>
      <geometry>
        <cylinder length="0.08" radius="0.1"/>
      </geometry>
      <surface>
        <friction>
          <ode>
            <mu>1.0</mu>
            <mu2>1.0</mu2>
          </ode>
        </friction>
      </surface>
    </collision>
  </link>
  <link name="wheel_right">
    <inertial>
      <origin rpy="0.0 0.0 0.0" xyz="0.0 0.0 0.0"/>
      <mass value="1.0"/>
      <inertia ixx="0.00389878" ixy="0.0" ixz="0.0" iyy="0.00389878" iyz="0.0" izz="0.00712177"/>
    </inertial>
    <visual>
      <origin rpy="0.0 0.0 0.0" xyz="-0.0 0.0 -0.034"/>
      <geometry>
        <mesh filename="package://nova_carter_description/meshes/nova_carter_wheel_left.obj"/>
      </geometry>
    </visual>
    <collision>
      <origin rpy="0.0 0.0 -2.6179938" xyz="-0.0 0.0 -0.034"/>
      <geometry>
        <cylinder length="0.02" radius="0.14"/>
      </geometry>
      <surface>
        <friction>
          <ode>
            <mu>1.0</mu>
            <mu2>1.0</mu2>
          </ode>
        </friction>
      </surface>
    </collision>
    <collision>
      <origin rpy="0.0 0.0 -2.6179938" xyz="-0.0 0.0 -0.034"/>
      <geometry>
        <cylinder length="0.06" radius="0.125"/>
      </geometry>
      <surface>
        <friction>
          <ode>
            <mu>1.0</mu>
            <mu2>1.0</mu2>
          </ode>
        </friction>
      </surface>
    </collision>
    <collision>
      <origin rpy="0.0 0.0 -2.6179938" xyz="-0.0 0.0 -0.034"/>
      <geometry>
        <cylinder length="0.08" radius="0.1"/>
      </geometry>
      <surface>
        <friction>
          <ode>
            <mu>1.0</mu>
            <mu2>1.0</mu2>
          </ode>
        </friction>
      </surface>
    </collision>
  </link>
  <!-- common stuff -->
  <!-- <xacro:include filename="$(find robot_description)/urdf/common.gazebo.xacro" /> -->
  <!-- measured from model -->
  <!--property name="shoulder_height" value="0.089159" /-->
  <!--property name="shoulder_offset" value="0.13585" /-->
  <!-- shoulder_offset - elbow_offset + wrist_1_length = 0.10915 -->
  <!--property name="upper_arm_length" value="0.42500" /-->
  <!--property name="elbow_offset" value="0.1197" /-->
  <!-- CAD measured -->
  <!--property name="forearm_length" value="0.39225" /-->
  <!--property name="wrist_1_length" value="0.093" /-->
  <!-- CAD measured -->
  <!--property name="wrist_2_length" value="0.09465" /-->
  <!-- In CAD this distance is 0.930, but in the spec it is 0.09465 -->
  <!--property name="wrist_3_length" value="0.0823" /-->
  <!-- manually measured -->
  <link name="base_link">
    <visual>
      <geometry>
        <mesh filename="package://robot_description/meshes/ur5/visual/base.dae"/>
      </geometry>
      <material name="LightGrey">
        <color rgba="0.7 0.7 0.7 1.0"/>
      </material>
    </visual>
    <collision>
      <geometry>
        <mesh filename="package://robot_description/meshes/ur5/collision/base.stl"/>
      </geometry>
    </collision>
    <inertial>
      <mass value="40.0"/>
      <origin rpy="0 0 0" xyz="0.0 0.0 0.0"/>
      <inertia ixx="0.17499993000000003" ixy="0.0" ixz="0.0" iyy="0.17499993000000003" iyz="0.0" izz="0.2"/>
    </inertial>
  </link>
  <joint name="shoulder_pan_joint" type="revolute">
    <parent link="base_link"/>
    <child link="shoulder_link"/>
    <origin rpy="0.0 0.0 0.0" xyz="0.0 0.0 0.089159"/>
    <axis xyz="0 0 1"/>
    <limit effort="150.0" lower="-6.283185307179586" upper="6.283185307179586" velocity="3.15"/>
    <dynamics damping="0.0" friction="0.0"/>
  </joint>
  <link name="shoulder_link">
    <visual>
      <geometry>
        <mesh filename="package://robot_description/meshes/ur5/visual/shoulder.dae"/>
      </geometry>
      <material name="LightGrey">
        <color rgba="0.7 0.7 0.7 1.0"/>
      </material>
    </visual>
    <collision>
      <geometry>
        <mesh filename="package://robot_description/meshes/ur5/collision/shoulder.stl"/>
      </geometry>
    </collision>
    <inertial>
      <mass value="3.7"/>
      <origin rpy="0 0 0" xyz="0.0 0.0 0.0"/>
      <inertia ixx="0.010267495893" ixy="0.0" ixz="0.0" iyy="0.010267495893" iyz="0.0" izz="0.00666"/>
    </inertial>
  </link>
  <joint name="shoulder_lift_joint" type="revolute">
    <parent link="shoulder_link"/>
    <child link="upper_arm_link"/>
    <origin rpy="0.0 1.5707963267948966 0.0" xyz="0.0 0.13585 0.0"/>
    <axis xyz="0 1 0"/>
    <limit effort="150.0" lower="-6.283185307179586" upper="6.283185307179586" velocity="3.15"/>
    <dynamics damping="0.0" friction="0.0"/>
  </joint>
  <link name="upper_arm_link">
    <visual>
      <geometry>
        <mesh filename="package://robot_description/meshes/ur5/visual/upperarm.dae"/>
      </geometry>
      <material name="LightGrey">
        <color rgba="0.7 0.7 0.7 1.0"/>
      </material>
    </visual>
    <collision>
      <geometry>
        <mesh filename="package://robot_description/meshes/ur5/collision/upperarm.stl"/>
      </geometry>
    </collision>
    <inertial>
      <mass value="8.393"/>
      <origin rpy="0 0 0" xyz="0.0 0.0 0.28"/>
      <inertia ixx="0.22689067591036005" ixy="0.0" ixz="0.0" iyy="0.22689067591036005" iyz="0.0" izz="0.0151074"/>
    </inertial>
  </link>
  <joint name="elbow_joint" type="revolute">
    <parent link="upper_arm_link"/>
    <child link="forearm_link"/>
    <origin rpy="0.0 0.0 0.0" xyz="0.0 -0.1197 0.425"/>
    <axis xyz="0 1 0"/>
    <limit effort="150.0" lower="-3.141592653589793" upper="3.141592653589793" velocity="3.15"/>
    <dynamics damping="0.0" friction="0.0"/>
  </joint>
  <link name="forearm_link">
    <visual>
      <geometry>
        <mesh filename="package://robot_description/meshes/ur5/visual/forearm.dae"/>
      </geometry>
      <material name="LightGrey">
        <color rgba="0.7 0.7 0.7 1.0"/>
      </material>
    </visual>
    <collision>
      <geometry>
        <mesh filename="package://robot_description/meshes/ur5/collision/forearm.stl"/>
      </geometry>
    </collision>
    <inertial>
      <mass value="2.275"/>
      <origin rpy="0 0 0" xyz="0.0 0.0 0.25"/>
      <inertia ixx="0.04944331355599999" ixy="0.0" ixz="0.0" iyy="0.04944331355599999" iyz="0.0" izz="0.004095"/>
    </inertial>
  </link>
  <joint name="wrist_1_joint" type="revolute">
    <parent link="forearm_link"/>
    <child link="wrist_1_link"/>
    <origin rpy="0.0 1.5707963267948966 0.0" xyz="0.0 0.0 0.39225"/>
    <axis xyz="0 1 0"/>
    <limit effort="28.0" lower="-6.283185307179586" upper="6.283185307179586" velocity="3.2"/>
    <dynamics damping="0.0" friction="0.0"/>
  </joint>
  <link name="wrist_1_link">
    <visual>
      <geometry>
        <mesh filename="package://robot_description/meshes/ur5/visual/wrist1.dae"/>
      </geometry>
      <material name="LightGrey">
        <color rgba="0.7 0.7 0.7 1.0"/>
      </material>
    </visual>
    <collision>
      <geometry>
        <mesh filename="package://robot_description/meshes/ur5/collision/wrist1.stl"/>
      </geometry>
    </collision>
    <inertial>
      <mass value="1.219"/>
      <origin rpy="0 0 0" xyz="0.0 0.0 0.0"/>
      <inertia ixx="0.11117275553087999" ixy="0.0" ixz="0.0" iyy="0.11117275553087999" iyz="0.0" izz="0.21942"/>
    </inertial>
  </link>
  <joint name="wrist_2_joint" type="revolute">
    <parent link="wrist_1_link"/>
    <child link="wrist_2_link"/>
    <origin rpy="0.0 0.0 0.0" xyz="0.0 0.093 0.0"/>
    <axis xyz="0 0 1"/>
    <limit effort="28.0" lower="-6.283185307179586" upper="6.283185307179586" velocity="3.2"/>
    <dynamics damping="0.0" friction="0.0"/>
  </joint>
  <link name="wrist_2_link">
    <visual>
      <geometry>
        <mesh filename="package://robot_description/meshes/ur5/visual/wrist2.dae"/>
      </geometry>
      <material name="LightGrey">
        <color rgba="0.7 0.7 0.7 1.0"/>
      </material>
    </visual>
    <collision>
      <geometry>
        <mesh filename="package://robot_description/meshes/ur5/collision/wrist2.stl"/>
      </geometry>
    </collision>
    <inertial>
      <mass value="1.219"/>
      <origin rpy="0 0 0" xyz="0.0 0.0 0.0"/>
      <inertia ixx="0.11117275553087999" ixy="0.0" ixz="0.0" iyy="0.11117275553087999" iyz="0.0" izz="0.21942"/>
    </inertial>
  </link>
  <joint name="wrist_3_joint" type="revolute">
    <parent link="wrist_2_link"/>
    <child link="wrist_3_link"/>
    <origin rpy="0.0 0.0 0.0" xyz="0.0 0.0 0.09465"/>
    <axis xyz="0 1 0"/>
    <limit effort="28.0" lower="-6.283185307179586" upper="6.283185307179586" velocity="3.2"/>
    <dynamics damping="0.0" friction="0.0"/>
  </joint>
  <link name="wrist_3_link">
    <visual>
      <geometry>
        <mesh filename="package://robot_description/meshes/ur5/visual/wrist3.dae"/>
      </geometry>
      <material name="LightGrey">
        <color rgba="0.7 0.7 0.7 1.0"/>
      </material>
    </visual>
    <collision>
      <geometry>
        <mesh filename="package://robot_description/meshes/ur5/collision/wrist3.stl"/>
      </geometry>
    </collision>
    <inertial>
      <mass value="0.1879"/>
      <origin rpy="0 0 0" xyz="0.0 0.0 0.0"/>
      <inertia ixx="0.017136473145408" ixy="0.0" ixz="0.0" iyy="0.017136473145408" iyz="0.0" izz="0.033822"/>
    </inertial>
  </link>
  <joint name="ee_fixed_joint" type="fixed">
    <parent link="wrist_3_link"/>
    <child link="ee_link"/>
    <origin rpy="0.0 0.0 1.5707963267948966" xyz="0.0 0.0823 0.0"/>
  </joint>
  <link name="ee_link">
    <collision>
      <geometry>
        <box size="0.01 0.01 0.01"/>
      </geometry>
      <origin rpy="0 0 0" xyz="-0.01 0 0"/>
    </collision>
  </link>
  <!-- ROS base_link to UR 'Base' Coordinates transform -->
  <link name="base"/>
  <joint name="base_link-base_fixed_joint" type="fixed">
    <!-- NOTE: this rotation is only needed as long as base_link itself is
                 not corrected wrt the real robot (ie: rotated over 180
                 degrees)
      -->
    <origin rpy="0 0 -3.141592653589793" xyz="0 0 0"/>
    <parent link="base_link"/>
    <child link="base"/>
  </joint>
  <!-- Frame coincident with all-zeros TCP on UR controller -->
  <link name="tool0"/>
  <joint name="wrist_3_link-tool0_fixed_joint" type="fixed">
    <origin rpy="-1.5707963267948966 0 0" xyz="0 0.0823 0"/>
    <parent link="wrist_3_link"/>
    <child link="tool0"/>
  </joint>
  <link name="ur5_mount">
  </link>
  <joint name="nova_ur_joint" type="fixed">
    <origin rpy="0 0 0" xyz="-0.25 0 0.48"/>
    <parent link="base_footprint"/>
    <child link="ur5_mount"/>
  </joint>
  <joint name="nova_mount_joint" type="fixed">
    <parent link="ur5_mount"/>
    <child link="base_link"/>
    <origin rpy="0.0 0.0 0.0" xyz="0.0 0.0 0.0"/>
  </joint>
</robot>
